Workbook

Sheet RTD
A2: ="UX" &tenure!G6& " Index" -> UXU26 Index | B2: =tenure!I6 -> 17.050 | C2: =tenure!J6 -> 16.9353
A3: ="UX" &tenure!G7& " Index" -> UXV26 Index | B3: =tenure!I7 -> 18.850 | C3: =tenure!J7 -> 18.7002
A4: ="UX" &tenure!G8& " Index" -> UXX26 Index | B4: =tenure!I8 -> 19.450 | C4: =tenure!J8 -> 19.3599
A5: ="UX" &tenure!G9& " Index" -> UXZ26 Index | B5: =tenure!I9 -> 19.600 | C5: =tenure!J9 -> 19.5021
A6: ="UX" &tenure!G10& " Index" -> UXF27 Index | B6: =tenure!I10 -> 20.650 | C6: =tenure!J10 -> 20.6476
A7: ="UX" &tenure!G11& " Index" -> UXG27 Index | B7: =tenure!I11 -> 21.200 | C7: =tenure!J11 -> 21.1518
A8: ="UX" &tenure!G12& " Index" -> UXH27 Index | B8: =tenure!I12 -> 21.450 | C8: =tenure!J12 -> 21.425
A9: ="UX" &tenure!G13& " Index" -> UXJ27 Index | B9: =tenure!I13 -> 21.750 | C9: =tenure!J13 -> 21.700
A10: ="UX" &tenure!G14& " Index" -> UXK27 Index | B10: =tenure!I14 -> 21.975 | C10: =tenure!J14 -> 21.975
A11: ="UX" &tenure!G15& " Index" -> UXM27 Index | B11: =tenure!I15 -> #N/A | C11: =tenure!J15 -> #N/A

Sheet tenure
A1: today's date | C1: hence first contract | E1: row # of 1st live
A2: =TODAY() -> 46265 | C2: =LOOKUP($A$2, $E$6:$E$257, $F$6:$F$257) -> U26 | E2: =MATCH(C2, $F$6:$F$257, 0) -> 69
A4: VX/FVS | D4: maturiry date | I4: CFE
A5: month+1 | B5: year of +1 month | C5: third Friday | D5: third Friday-30 | E5: start of tenure (SR3) | F5: cont | G5: live contracts from 1st | H5: live contracts from 1st | I5: Last | J5: Settle | L5: S1 | P5: F | Q5: 1 | R5: Jan
A6: =MOD(VLOOKUP(LEFT(F6,1),$P$5:$Q$16,2,0),12)+1 -> 2 | B6: =IF(A6>1, RIGHT(F6,2),RIGHT(F7,2)) -> 21 | C6: =DATE(B6+100, A6, 1) + 14 + MOD(6 - WEEKDAY(DATE(B6+100, A6, 1)), 7) -> 44246 | D6: =C6-30 -> 44216 | E6: =D5+1 -> #VALUE! | F6: F21 | G6: {=_xlfn._xlws.FILTER( $F$6:$F$257, ROW( $F$6:$F$257) >= $E$2+5, 0)} -> U26 | H6: =VLOOKUP(LEFT(G6,1),$P$5:$R$16,3,0)& RIGHT(G6,2) -> Sep26 | I6: =IF(ISNUMBER(VALUE(RTD("tt.rtd",,"Instr",$I$4,"VX","FUTURE",$H6,I$5))),RTD("tt.rtd",,"Instr",$I$4,"VX","FUTURE",$H6,I$5),J6) -> 17.050 | J6: =IF(ISNUMBER(VALUE(RTD("tt.rtd",,"Instr",$I$4,"VX","FUTURE",$H6,J$5))),RTD("tt.rtd",,"Instr",$I$4,"VX","FUTURE",$H6,J$5),NA()) -> 16.9353 | L6: =(I6-I7)*100 -> -180 | P6: G | Q6: 2 | R6: Feb
A7: =MOD(VLOOKUP(LEFT(F7,1),$P$5:$Q$16,2,0),12)+1 -> 3 | B7: =IF(A7>1, RIGHT(F7,2),RIGHT(F8,2)) -> 21 | C7: =DATE(B7+100, A7, 1) + 14 + MOD(6 - WEEKDAY(DATE(B7+100, A7, 1)), 7) -> 44274 | D7: =C7-30 -> 44244 | E7: =D6+1 -> 44217 | F7: G21 | G7: V26 | H7: =VLOOKUP(LEFT(G7,1),$P$5:$R$16,3,0)& RIGHT(G7,2) -> Oct26 | I7: =IF(ISNUMBER(VALUE(RTD("tt.rtd",,"Instr",$I$4,"VX","FUTURE",$H7,I$5))),RTD("tt.rtd",,"Instr",$I$4,"VX","FUTURE",$H7,I$5),J7) -> 18.850 | J7: =IF(ISNUMBER(VALUE(RTD("tt.rtd",,"Instr",$I$4,"VX","FUTURE",$H7,J$5))),RTD("tt.rtd",,"Instr",$I$4,"VX","FUTURE",$H7,J$5),NA()) -> 18.7002 | L7: =(I7-I8)*100 -> -60 | P7: H | Q7: 3 | R7: Mar
A8: =MOD(VLOOKUP(LEFT(F8,1),$P$5:$Q$16,2,0),12)+1 -> 4 | B8: =IF(A8>1, RIGHT(F8,2),RIGHT(F9,2)) -> 21 | C8: =DATE(B8+100, A8, 1) + 14 + MOD(6 - WEEKDAY(DATE(B8+100, A8, 1)), 7) -> 44302 | D8: =C8-30 -> 44272 | E8: =D7+1 -> 44245 | F8: H21 | G8: X26 | H8: =VLOOKUP(LEFT(G8,1),$P$5:$R$16,3,0)& RIGHT(G8,2) -> Nov26 | I8: =IF(ISNUMBER(VALUE(RTD("tt.rtd",,"Instr",$I$4,"VX","FUTURE",$H8,I$5))),RTD("tt.rtd",,"Instr",$I$4,"VX","FUTURE",$H8,I$5),J8) -> 19.450 | J8: =IF(ISNUMBER(VALUE(RTD("tt.rtd",,"Instr",$I$4,"VX","FUTURE",$H8,J$5))),RTD("tt.rtd",,"Instr",$I$4,"VX","FUTURE",$H8,J$5),NA()) -> 19.3599 | L8: =(I8-I9)*100 -> -15 | P8: J | Q8: 4 | R8: Apr
A9: =MOD(VLOOKUP(LEFT(F9,1),$P$5:$Q$16,2,0),12)+1 -> 5 | B9: =IF(A9>1, RIGHT(F9,2),RIGHT(F10,2)) -> 21 | C9: =DATE(B9+100, A9, 1) + 14 + MOD(6 - WEEKDAY(DATE(B9+100, A9, 1)), 7) -> 44337 | D9: =C9-30 -> 44307 | E9: =D8+1 -> 44273 | F9: J21 | G9: Z26 | H9: =VLOOKUP(LEFT(G9,1),$P$5:$R$16,3,0)& RIGHT(G9,2) -> Dec26 | I9: =IF(ISNUMBER(VALUE(RTD("tt.rtd",,"Instr",$I$4,"VX","FUTURE",$H9,I$5))),RTD("tt.rtd",,"Instr",$I$4,"VX","FUTURE",$H9,I$5),J9) -> 19.600 | J9: =IF(ISNUMBER(VALUE(RTD("tt.rtd",,"Instr",$I$4,"VX","FUTURE",$H9,J$5))),RTD("tt.rtd",,"Instr",$I$4,"VX","FUTURE",$H9,J$5),NA()) -> 19.5021 | L9: =(I9-I10)*100 -> -105 | P9: K | Q9: 5 | R9: May
A10: =MOD(VLOOKUP(LEFT(F10,1),$P$5:$Q$16,2,0),12)+1 -> 6 | B10: =IF(A10>1, RIGHT(F10,2),RIGHT(F11,2)) -> 21 | C10: =DATE(B10+100, A10, 1) + 14 + MOD(6 - WEEKDAY(DATE(B10+100, A10, 1)), 7) -> 44365 | D10: =C10-30 -> 44335 | E10: =D9+1 -> 44308 | F10: K21 | G10: F27 | H10: =VLOOKUP(LEFT(G10,1),$P$5:$R$16,3,0)& RIGHT(G10,2) -> Jan27 | I10: =IF(ISNUMBER(VALUE(RTD("tt.rtd",,"Instr",$I$4,"VX","FUTURE",$H10,I$5))),RTD("tt.rtd",,"Instr",$I$4,"VX","FUTURE",$H10,I$5),J10) -> 20.650 | J10: =IF(ISNUMBER(VALUE(RTD("tt.rtd",,"Instr",$I$4,"VX","FUTURE",$H10,J$5))),RTD("tt.rtd",,"Instr",$I$4,"VX","FUTURE",$H10,J$5),NA()) -> 20.6476 | L10: =(I10-I11)*100 -> -55 | P10: M | Q10: 6 | R10: Jun
A11: =MOD(VLOOKUP(LEFT(F11,1),$P$5:$Q$16,2,0),12)+1 -> 7 | B11: =IF(A11>1, RIGHT(F11,2),RIGHT(F12,2)) -> 21 | C11: =DATE(B11+100, A11, 1) + 14 + MOD(6 - WEEKDAY(DATE(B11+100, A11, 1)), 7) -> 44393 | D11: =C11-30 -> 44363 | E11: =D10+1 -> 44336 | F11: M21 | G11: G27 | H11: =VLOOKUP(LEFT(G11,1),$P$5:$R$16,3,0)& RIGHT(G11,2) -> Feb27 | I11: =IF(ISNUMBER(VALUE(RTD("tt.rtd",,"Instr",$I$4,"VX","FUTURE",$H11,I$5))),RTD("tt.rtd",,"Instr",$I$4,"VX","FUTURE",$H11,I$5),J11) -> 21.200 | J11: =IF(ISNUMBER(VALUE(RTD("tt.rtd",,"Instr",$I$4,"VX","FUTURE",$H11,J$5))),RTD("tt.rtd",,"Instr",$I$4,"VX","FUTURE",$H11,J$5),NA()) -> 21.1518 | L11: =(I11-I12)*100 -> -25 | P11: N | Q11: 7 | R11: Jul
A12: =MOD(VLOOKUP(LEFT(F12,1),$P$5:$Q$16,2,0),12)+1 -> 8 | B12: =IF(A12>1, RIGHT(F12,2),RIGHT(F13,2)) -> 21 | C12: =DATE(B12+100, A12, 1) + 14 + MOD(6 - WEEKDAY(DATE(B12+100, A12, 1)), 7) -> 44428 | D12: =C12-30 -> 44398 | E12: =D11+1 -> 44364 | F12: N21 | G12: H27 | H12: =VLOOKUP(LEFT(G12,1),$P$5:$R$16,3,0)& RIGHT(G12,2) -> Mar27 | I12: =IF(ISNUMBER(VALUE(RTD("tt.rtd",,"Instr",$I$4,"VX","FUTURE",$H12,I$5))),RTD("tt.rtd",,"Instr",$I$4,"VX","FUTURE",$H12,I$5),J12) -> 21.450 | J12: =IF(ISNUMBER(VALUE(RTD("tt.rtd",,"Instr",$I$4,"VX","FUTURE",$H12,J$5))),RTD("tt.rtd",,"Instr",$I$4,"VX","FUTURE",$H12,J$5),NA()) -> 21.425 | L12: =(I12-I13)*100 -> -30 | P12: Q | Q12: 8 | R12: Aug
A13: =MOD(VLOOKUP(LEFT(F13,1),$P$5:$Q$16,2,0),12)+1 -> 9 | B13: =IF(A13>1, RIGHT(F13,2),RIGHT(F14,2)) -> 21 | C13: =DATE(B13+100, A13, 1) + 14 + MOD(6 - WEEKDAY(DATE(B13+100, A13, 1)), 7) -> 44456 | D13: =C13-30 -> 44426 | E13: =D12+1 -> 44399 | F13: Q21 | G13: J27 | H13: =VLOOKUP(LEFT(G13,1),$P$5:$R$16,3,0)& RIGHT(G13,2) -> Apr27 | I13: =IF(ISNUMBER(VALUE(RTD("tt.rtd",,"Instr",$I$4,"VX","FUTURE",$H13,I$5))),RTD("tt.rtd",,"Instr",$I$4,"VX","FUTURE",$H13,I$5),J13) -> 21.750 | J13: =IF(ISNUMBER(VALUE(RTD("tt.rtd",,"Instr",$I$4,"VX","FUTURE",$H13,J$5))),RTD("tt.rtd",,"Instr",$I$4,"VX","FUTURE",$H13,J$5),NA()) -> 21.700 | L13: =(I13-I14)*100 -> -22.5 | P13: U | Q13: 9 | R13: Sep
A14: =MOD(VLOOKUP(LEFT(F14,1),$P$5:$Q$16,2,0),12)+1 -> 10 | B14: =IF(A14>1, RIGHT(F14,2),RIGHT(F15,2)) -> 21 | C14: =DATE(B14+100, A14, 1) + 14 + MOD(6 - WEEKDAY(DATE(B14+100, A14, 1)), 7) -> 44484 | D14: =C14-30 -> 44454 | E14: =D13+1 -> 44427 | F14: U21 | G14: K27 | H14: =VLOOKUP(LEFT(G14,1),$P$5:$R$16,3,0)& RIGHT(G14,2) -> May27 | I14: =IF(ISNUMBER(VALUE(RTD("tt.rtd",,"Instr",$I$4,"VX","FUTURE",$H14,I$5))),RTD("tt.rtd",,"Instr",$I$4,"VX","FUTURE",$H14,I$5),J14) -> 21.975 | J14: =IF(ISNUMBER(VALUE(RTD("tt.rtd",,"Instr",$I$4,"VX","FUTURE",$H14,J$5))),RTD("tt.rtd",,"Instr",$I$4,"VX","FUTURE",$H14,J$5),NA()) -> 21.975 | L14: =(I14-I15)*100 -> #N/A | P14: V | Q14: 10 | R14: Oct
A15: =MOD(VLOOKUP(LEFT(F15,1),$P$5:$Q$16,2,0),12)+1 -> 11 | B15: =IF(A15>1, RIGHT(F15,2),RIGHT(F16,2)) -> 21 | C15: =DATE(B15+100, A15, 1) + 14 + MOD(6 - WEEKDAY(DATE(B15+100, A15, 1)), 7) -> 44519 | D15: =C15-30 -> 44489 | E15: =D14+1 -> 44455 | F15: V21 | G15: M27 | H15: =VLOOKUP(LEFT(G15,1),$P$5:$R$16,3,0)& RIGHT(G15,2) -> Jun27 | I15: =IF(ISNUMBER(VALUE(RTD("tt.rtd",,"Instr",$I$4,"VX","FUTURE",$H15,I$5))),RTD("tt.rtd",,"Instr",$I$4,"VX","FUTURE",$H15,I$5),J15) -> #N/A | J15: =IF(ISNUMBER(VALUE(RTD("tt.rtd",,"Instr",$I$4,"VX","FUTURE",$H15,J$5))),RTD("tt.rtd",,"Instr",$I$4,"VX","FUTURE",$H15,J$5),NA()) -> #N/A | L15: =(I15-I16)*100 -> #N/A | P15: X | Q15: 11 | R15: Nov
A16: =MOD(VLOOKUP(LEFT(F16,1),$P$5:$Q$16,2,0),12)+1 -> 12 | B16: =IF(A16>1, RIGHT(F16,2),RIGHT(F17,2)) -> 21 | C16: =DATE(B16+100, A16, 1) + 14 + MOD(6 - WEEKDAY(DATE(B16+100, A16, 1)), 7) -> 44547 | D16: =C16-30 -> 44517 | E16: =D15+1 -> 44490 | F16: X21 | G16: N27 | H16: =VLOOKUP(LEFT(G16,1),$P$5:$R$16,3,0)& RIGHT(G16,2) -> Jul27 | P16: Z | Q16: 12 | R16: Dec
A17: =MOD(VLOOKUP(LEFT(F17,1),$P$5:$Q$16,2,0),12)+1 -> 1 | B17: =IF(A17>1, RIGHT(F17,2),RIGHT(F18,2)) -> 22 | C17: =DATE(B17+100, A17, 1) + 14 + MOD(6 - WEEKDAY(DATE(B17+100, A17, 1)), 7) -> 44582 | D17: =C17-30 -> 44552 | E17: =D16+1 -> 44518 | F17: Z21 | G17: Q27 | H17: =VLOOKUP(LEFT(G17,1),$P$5:$R$16,3,0)& RIGHT(G17,2) -> Aug27
A18: =MOD(VLOOKUP(LEFT(F18,1),$P$5:$Q$16,2,0),12)+1 -> 2 | B18: =IF(A18>1, RIGHT(F18,2),RIGHT(F19,2)) -> 22 | C18: =DATE(B18+100, A18, 1) + 14 + MOD(6 - WEEKDAY(DATE(B18+100, A18, 1)), 7) -> 44610 | D18: =C18-30 -> 44580 | E18: =D17+1 -> 44553 | F18: F22 | G18: U27 | H18: =VLOOKUP(LEFT(G18,1),$P$5:$R$16,3,0)& RIGHT(G18,2) -> Sep27
A19: =MOD(VLOOKUP(LEFT(F19,1),$P$5:$Q$16,2,0),12)+1 -> 3 | B19: =IF(A19>1, RIGHT(F19,2),RIGHT(F20,2)) -> 22 | C19: =DATE(B19+100, A19, 1) + 14 + MOD(6 - WEEKDAY(DATE(B19+100, A19, 1)), 7) -> 44638 | D19: =C19-30 -> 44608 | E19: =D18+1 -> 44581 | F19: G22 | G19: V27 | H19: =VLOOKUP(LEFT(G19,1),$P$5:$R$16,3,0)& RIGHT(G19,2) -> Oct27 | I19: STATUS
A20: =MOD(VLOOKUP(LEFT(F20,1),$P$5:$Q$16,2,0),12)+1 -> 4 | B20: =IF(A20>1, RIGHT(F20,2),RIGHT(F21,2)) -> 22 | C20: =DATE(B20+100, A20, 1) + 14 + MOD(6 - WEEKDAY(DATE(B20+100, A20, 1)), 7) -> 44666 | D20: =C20-30 -> 44636 | E20: =D19+1 -> 44609 | F20: H22 | G20: X27 | H20: =VLOOKUP(LEFT(G20,1),$P$5:$R$16,3,0)& RIGHT(G20,2) -> Nov27 | I20: =RTD("tt.rtd",,"Instr",$I$4,"VX","FUTURE",$H7,I$19) -> Open
A21: =MOD(VLOOKUP(LEFT(F21,1),$P$5:$Q$16,2,0),12)+1 -> 5 | B21: =IF(A21>1, RIGHT(F21,2),RIGHT(F22,2)) -> 22 | C21: =DATE(B21+100, A21, 1) + 14 + MOD(6 - WEEKDAY(DATE(B21+100, A21, 1)), 7) -> 44701 | D21: =C21-30 -> 44671 | E21: =D20+1 -> 44637 | F21: J22 | G21: Z27 | H21: =VLOOKUP(LEFT(G21,1),$P$5:$R$16,3,0)& RIGHT(G21,2) -> Dec27
A22: =MOD(VLOOKUP(LEFT(F22,1),$P$5:$Q$16,2,0),12)+1 -> 6 | B22: =IF(A22>1, RIGHT(F22,2),RIGHT(F23,2)) -> 22 | C22: =DATE(B22+100, A22, 1) + 14 + MOD(6 - WEEKDAY(DATE(B22+100, A22, 1)), 7) -> 44729 | D22: =C22-30 -> 44699 | E22: =D21+1 -> 44672 | F22: K22 | G22: F28 | H22: =VLOOKUP(LEFT(G22,1),$P$5:$R$16,3,0)& RIGHT(G22,2) -> Jan28 | K22: =[1]VIX!B4 -> 46258 | L22: VIX latest
A23: =MOD(VLOOKUP(LEFT(F23,1),$P$5:$Q$16,2,0),12)+1 -> 7 | B23: =IF(A23>1, RIGHT(F23,2),RIGHT(F24,2)) -> 22 | C23: =DATE(B23+100, A23, 1) + 14 + MOD(6 - WEEKDAY(DATE(B23+100, A23, 1)), 7) -> 44757 | D23: =C23-30 -> 44727 | E23: =D22+1 -> 44700 | F23: M22 | G23: G28 | H23: =VLOOKUP(LEFT(G23,1),$P$5:$R$16,3,0)& RIGHT(G23,2) -> Feb28 | K23: =[1]VOXX!B4 -> 46258 | L23: VOXX latest
A24: =MOD(VLOOKUP(LEFT(F24,1),$P$5:$Q$16,2,0),12)+1 -> 8 | B24: =IF(A24>1, RIGHT(F24,2),RIGHT(F25,2)) -> 22 | C24: =DATE(B24+100, A24, 1) + 14 + MOD(6 - WEEKDAY(DATE(B24+100, A24, 1)), 7) -> 44792 | D24: =C24-30 -> 44762 | E24: =D23+1 -> 44728 | F24: N22 | G24: H28 | H24: =VLOOKUP(LEFT(G24,1),$P$5:$R$16,3,0)& RIGHT(G24,2) -> Mar28 | K24: =[1]SPX!B4 -> 46258 | L24: SPX latest
A25: =MOD(VLOOKUP(LEFT(F25,1),$P$5:$Q$16,2,0),12)+1 -> 9 | B25: =IF(A25>1, RIGHT(F25,2),RIGHT(F26,2)) -> 22 | C25: =DATE(B25+100, A25, 1) + 14 + MOD(6 - WEEKDAY(DATE(B25+100, A25, 1)), 7) -> 44820 | D25: =C25-30 -> 44790 | E25: =D24+1 -> 44763 | F25: Q22 | G25: J28 | H25: =VLOOKUP(LEFT(G25,1),$P$5:$R$16,3,0)& RIGHT(G25,2) -> Apr28
A26: =MOD(VLOOKUP(LEFT(F26,1),$P$5:$Q$16,2,0),12)+1 -> 10 | B26: =IF(A26>1, RIGHT(F26,2),RIGHT(F27,2)) -> 22 | C26: =DATE(B26+100, A26, 1) + 14 + MOD(6 - WEEKDAY(DATE(B26+100, A26, 1)), 7) -> 44855 | D26: =C26-30 -> 44825 | E26: =D25+1 -> 44791 | F26: U22 | G26: K28 | H26: =VLOOKUP(LEFT(G26,1),$P$5:$R$16,3,0)& RIGHT(G26,2) -> May28
A27: =MOD(VLOOKUP(LEFT(F27,1),$P$5:$Q$16,2,0),12)+1 -> 11 | B27: =IF(A27>1, RIGHT(F27,2),RIGHT(F28,2)) -> 22 | C27: =DATE(B27+100, A27, 1) + 14 + MOD(6 - WEEKDAY(DATE(B27+100, A27, 1)), 7) -> 44883 | D27: =C27-30 -> 44853 | E27: =D26+1 -> 44826 | F27: V22 | G27: M28 | H27: =VLOOKUP(LEFT(G27,1),$P$5:$R$16,3,0)& RIGHT(G27,2) -> Jun28
A28: =MOD(VLOOKUP(LEFT(F28,1),$P$5:$Q$16,2,0),12)+1 -> 12 | B28: =IF(A28>1, RIGHT(F28,2),RIGHT(F29,2)) -> 22 | C28: =DATE(B28+100, A28, 1) + 14 + MOD(6 - WEEKDAY(DATE(B28+100, A28, 1)), 7) -> 44911 | D28: =C28-30 -> 44881 | E28: =D27+1 -> 44854 | F28: X22 | G28: N28 | H28: =VLOOKUP(LEFT(G28,1),$P$5:$R$16,3,0)& RIGHT(G28,2) -> Jul28
A29: =MOD(VLOOKUP(LEFT(F29,1),$P$5:$Q$16,2,0),12)+1 -> 1 | B29: =IF(A29>1, RIGHT(F29,2),RIGHT(F30,2)) -> 23 | C29: =DATE(B29+100, A29, 1) + 14 + MOD(6 - WEEKDAY(DATE(B29+100, A29, 1)), 7) -> 44946 | D29: =C29-30 -> 44916 | E29: =D28+1 -> 44882 | F29: Z22 | G29: Q28 | H29: =VLOOKUP(LEFT(G29,1),$P$5:$R$16,3,0)& RIGHT(G29,2) -> Aug28
A30: =MOD(VLOOKUP(LEFT(F30,1),$P$5:$Q$16,2,0),12)+1 -> 2 | B30: =IF(A30>1, RIGHT(F30,2),RIGHT(F31,2)) -> 23 | C30: =DATE(B30+100, A30, 1) + 14 + MOD(6 - WEEKDAY(DATE(B30+100, A30, 1)), 7) -> 44974 | D30: =C30-30 -> 44944 | E30: =D29+1 -> 44917 | F30: F23 | G30: U28 | H30: =VLOOKUP(LEFT(G30,1),$P$5:$R$16,3,0)& RIGHT(G30,2) -> Sep28
A31: =MOD(VLOOKUP(LEFT(F31,1),$P$5:$Q$16,2,0),12)+1 -> 3 | B31: =IF(A31>1, RIGHT(F31,2),RIGHT(F32,2)) -> 23 | C31: =DATE(B31+100, A31, 1) + 14 + MOD(6 - WEEKDAY(DATE(B31+100, A31, 1)), 7) -> 45002 | D31: =C31-30 -> 44972 | E31: =D30+1 -> 44945 | F31: G23 | G31: V28 | H31: =VLOOKUP(LEFT(G31,1),$P$5:$R$16,3,0)& RIGHT(G31,2) -> Oct28
A32: =MOD(VLOOKUP(LEFT(F32,1),$P$5:$Q$16,2,0),12)+1 -> 4 | B32: =IF(A32>1, RIGHT(F32,2),RIGHT(F33,2)) -> 23 | C32: =DATE(B32+100, A32, 1) + 14 + MOD(6 - WEEKDAY(DATE(B32+100, A32, 1)), 7) -> 45037 | D32: =C32-30 -> 45007 | E32: =D31+1 -> 44973 | F32: H23 | G32: X28 | H32: =VLOOKUP(LEFT(G32,1),$P$5:$R$16,3,0)& RIGHT(G32,2) -> Nov28
A33: =MOD(VLOOKUP(LEFT(F33,1),$P$5:$Q$16,2,0),12)+1 -> 5 | B33: =IF(A33>1, RIGHT(F33,2),RIGHT(F34,2)) -> 23 | C33: =DATE(B33+100, A33, 1) + 14 + MOD(6 - WEEKDAY(DATE(B33+100, A33, 1)), 7) -> 45065 | D33: =C33-30 -> 45035 | E33: =D32+1 -> 45008 | F33: J23 | G33: Z28 | H33: =VLOOKUP(LEFT(G33,1),$P$5:$R$16,3,0)& RIGHT(G33,2) -> Dec28
A34: =MOD(VLOOKUP(LEFT(F34,1),$P$5:$Q$16,2,0),12)+1 -> 6 | B34: =IF(A34>1, RIGHT(F34,2),RIGHT(F35,2)) -> 23 | C34: =DATE(B34+100, A34, 1) + 14 + MOD(6 - WEEKDAY(DATE(B34+100, A34, 1)), 7) -> 45093 | D34: =C34-30 -> 45063 | E34: =D33+1 -> 45036 | F34: K23 | G34: F29 | H34: =VLOOKUP(LEFT(G34,1),$P$5:$R$16,3,0)& RIGHT(G34,2) -> Jan29
A35: =MOD(VLOOKUP(LEFT(F35,1),$P$5:$Q$16,2,0),12)+1 -> 7 | B35: =IF(A35>1, RIGHT(F35,2),RIGHT(F36,2)) -> 23 | C35: =DATE(B35+100, A35, 1) + 14 + MOD(6 - WEEKDAY(DATE(B35+100, A35, 1)), 7) -> 45128 | D35: =C35-30 -> 45098 | E35: =D34+1 -> 45064 | F35: M23 | G35: G29 | H35: =VLOOKUP(LEFT(G35,1),$P$5:$R$16,3,0)& RIGHT(G35,2) -> Feb29
A36: =MOD(VLOOKUP(LEFT(F36,1),$P$5:$Q$16,2,0),12)+1 -> 8 | B36: =IF(A36>1, RIGHT(F36,2),RIGHT(F37,2)) -> 23 | C36: =DATE(B36+100, A36, 1) + 14 + MOD(6 - WEEKDAY(DATE(B36+100, A36, 1)), 7) -> 45156 | D36: =C36-30 -> 45126 | E36: =D35+1 -> 45099 | F36: N23 | G36: H29 | H36: =VLOOKUP(LEFT(G36,1),$P$5:$R$16,3,0)& RIGHT(G36,2) -> Mar29
... A189: =MOD(VLOOKUP(LEFT(F189,1),$P$5:$Q$16,2,0),12)+1 -> 5 | B189: =IF(A189>1, RIGHT(F189,2),RIGHT(F190,2)) -> 36 | C189: =DATE(B189+100, A189, 1) + 14 + MOD(6 - WEEKDAY(DATE(B189+100, A189, 1)), 7) -> 49811 | D189: =C189-30 -> 49781 | E189: =D188+1 -> 49754 | F189: J36 | G189: Z41 | H189: =VLOOKUP(LEFT(G189,1),$P$5:$R$16,3,0)& RIGHT(G189,2) -> Dec41
A190: =MOD(VLOOKUP(LEFT(F190,1),$P$5:$Q$16,2,0),12)+1 -> 6 | B190: =IF(A190>1, RIGHT(F190,2),RIGHT(F191,2)) -> 36 | C190: =DATE(B190+100, A190, 1) + 14 + MOD(6 - WEEKDAY(DATE(B190+100, A190, 1)), 7) -> 49846 | D190: =C190-30 -> 49816 | E190: =D189+1 -> 49782 | F190: K36 | H190: =VLOOKUP(LEFT(G190,1),$P$5:$R$16,3,0)& RIGHT(G190,2) -> #N/A
A191: =MOD(VLOOKUP(LEFT(F191,1),$P$5:$Q$16,2,0),12)+1 -> 7 | B191: =IF(A191>1, RIGHT(F191,2),RIGHT(F192,2)) -> 36 | C191: =DATE(B191+100, A191, 1) + 14 + MOD(6 - WEEKDAY(DATE(B191+100, A191, 1)), 7) -> 49874 | D191: =C191-30 -> 49844 | E191: =D190+1 -> 49817 | F191: M36 | H191: =VLOOKUP(LEFT(G191,1),$P$5:$R$16,3,0)& RIGHT(G191,2) -> #N/A
A192: =MOD(VLOOKUP(LEFT(F192,1),$P$5:$Q$16,2,0),12)+1 -> 8 | B192: =IF(A192>1, RIGHT(F192,2),RIGHT(F193,2)) -> 36 | C192: =DATE(B192+100, A192, 1) + 14 + MOD(6 - WEEKDAY(DATE(B192+100, A192, 1)), 7) -> 49902 | D192: =C192-30 -> 49872 | E192: =D191+1 -> 49845 | F192: N36 | H192: =VLOOKUP(LEFT(G192,1),$P$5:$R$16,3,0)& RIGHT(G192,2) -> #N/A
A193: =MOD(VLOOKUP(LEFT(F193,1),$P$5:$Q$16,2,0),12)+1 -> 9 | B193: =IF(A193>1, RIGHT(F193,2),RIGHT(F194,2)) -> 36 | C193: =DATE(B193+100, A193, 1) + 14 + MOD(6 - WEEKDAY(DATE(B193+100, A193, 1)), 7) -> 49937 | D193: =C193-30 -> 49907 | E193: =D192+1 -> 49873 | F193: Q36 | H193: =VLOOKUP(LEFT(G193,1),$P$5:$R$16,3,0)& RIGHT(G193,2) -> #N/A
...
